<mujoco model="Walker">
    <option timestep="0.004"/>
    <size memory="2G" />

    <statistic extent="2" center="0 0 1"/>

    <default>
        <joint damping=".1" armature="0.01" limited="true" solimplimit="0 .99 .01"/>
        <geom contype="1" conaffinity="0" friction=".7 .1 .1" /> <!-- solimp="0.95 0.99 0.001 2 0.5" solref = "0.02 0.9" /> -->
        <motor ctrlrange="-1 1" ctrllimited="true"/>
        <site size="0.01"/>
        <default class="walker">
            <geom material="self" type="capsule"/>
            <joint axis="0 -1 0"/>
        </default>
    </default>

    <asset>
        <texture name="blue_grid" type="2d" builtin="checker" rgb1=".02 .14 .44" rgb2=".27 .55 1" width="300" height="300" mark="edge" markrgb="1 1 1"/>
        <material name="blue_grid" texture="blue_grid" texrepeat="1 1" texuniform="true" reflectance=".2"/>

        <texture name="grey_grid" type="2d" builtin="checker" rgb1=".26 .26 .26" rgb2=".6 .6 .6" width="300" height="300" mark="edge" markrgb="1 1 1"/>
        <material name="grey_grid" texture="blue_grid" texrepeat="1 1" texuniform="true" reflectance=".2"/>
        <texture name="skybox" type="skybox" builtin="gradient" rgb1=".66 .79 1" rgb2=".9 .91 .93" width="800" height="800"/>

        <material name="self" rgba=".7 .5 .3 1"/>
        <material name="self_default" rgba=".7 .5 .3 1"/>
        <material name="self_highlight" rgba="0 .5 .3 1"/>
        <material name="effector" rgba=".7 .4 .2 1"/>
        <material name="effector_default" rgba=".7 .4 .2 1"/>
        <material name="effector_highlight" rgba="0 .5 .3 1"/>
        <material name="decoration" rgba=".2 .6 .3 1"/>
        <material name="eye" rgba="0 .2 1 1"/>
        <material name="target" rgba=".6 .3 .3 1"/>
        <material name="target_default" rgba=".6 .3 .3 1"/>
        <material name="target_highlight" rgba=".6 .3 .3 .4"/>
        <material name="site" rgba=".5 .5 .5 .3"/>
    </asset>

    <worldbody>
        <geom name="floor" type="plane" conaffinity="1" pos="998 0 0" size="1000 .8 .2" material="blue_grid" zaxis="0 0 1"/>
        <camera name="sideon" pos="0 -10 5" fovy="45" mode="targetbody" target="torso" />
        <camera name="float_far"  pos="-4 0 2" xyaxes="0 -1 0 .5 0 1" mode="trackcom" fovy="90"/>
        <body name="torso" pos="0 0 1.3" childclass="walker"> <!-- pos = 0 0 1.3 -->
            <light name="light" pos="0 0 2" mode="trackcom"/>
            <camera name="floating"  pos="-2 0 1" xyaxes="0 -1 0 .5 0 1" mode="trackcom" fovy="90"/>
            <camera name="egocentric"  pos=".25 0 .11" xyaxes="0 -1 0 0 0 1" fovy="90" />
            <joint name="rootz" axis="0 0 1" type="slide" limited="false" armature="0" damping="0"/>
            <joint name="rootx" axis="1 0 0" type="slide" limited="false" armature="0" damping="0"/>
            <joint name="rooty" axis="0 1 0" type="hinge" limited="false" armature="0" damping="0"/>
            <geom name="torso" size="0.07 0.3"/>
            <site name="torso_site" pos="0 0 0" size="0.01"/>
            <body name="right_thigh" pos="0 -.05 -0.3">
                <joint name="right_hip" range="-20 100"/>
                <geom name="right_thigh" pos="0 0 -0.225" size="0.05 0.225"/>
                <body name="right_leg" pos="0 0 -0.7">
                    <joint name="right_knee" pos="0 0 0.25" range="-150 0"/>
                    <geom name="right_leg" size="0.04 0.25"/>
                    <body name="right_foot" pos="0.06 0 -0.25">
                        <joint name="right_ankle" pos="-0.06 0 0" range="-45 45"/>
                        <geom name="right_foot" zaxis="1 0 0" size="0.05 0.1"/>
                    </body>
                </body>
            </body>
            <body name="left_thigh" pos="0 .05 -0.3" >
                <joint name="left_hip" range="-20 100"/>
                <geom name="left_thigh" pos="0 0 -0.225" size="0.05 0.225"/>
                <body name="left_leg" pos="0 0 -0.7">
                    <joint name="left_knee" pos="0 0 0.25" range="-150 0"/>
                    <geom name="left_leg" size="0.04 0.25"/>
                    <body name="left_foot" pos="0.06 0 -0.25">
                        <joint name="left_ankle" pos="-0.06 0 0" range="-45 45"/>
                        <geom name="left_foot" zaxis="1 0 0" size="0.05 0.1"/>
                    </body>
                </body>
            </body>
        </body>
    </worldbody>

    <sensor>
        <user name="Control" dim="6" user="0 0.1 0.0 1.0" />
        <user name="Height" dim="1" user="0 10.0 0.0 10.0" />
        <user name="Rotation" dim="1" user="0 3.0 0.0 5.0" />
        <user name="Speed" dim="1" user="0 1.0 0.0 1.0" />
        <framepos      name="trace0" objtype="site" objname="torso_site"/>
        <framepos      name="torso_position" objtype="xbody" objname="torso"/>
        <subtreecom    name="torso_subtreecom" body="torso"/>
        <subtreelinvel name="torso_subtreelinvel" body="torso"/>
        <framezaxis    name="torso_zaxis" objtype="xbody" objname="torso"/>
    </sensor>

    <actuator>
        <motor name="right_hip" joint="right_hip" gear="100"/>
        <motor name="right_knee" joint="right_knee" gear="50"/>
        <motor name="right_ankle" joint="right_ankle" gear="20"/>
        <motor name="left_hip" joint="left_hip" gear="100"/>
        <motor name="left_knee" joint="left_knee" gear="50"/>
        <motor name="left_ankle" joint="left_ankle" gear="20"/>
    </actuator>

</mujoco>