<mujoco model="piston_block">

    <asset>
        <!-- Define materials -->
        <material name="block_mat" rgba="0.2 0.2 0.8 0.5"/>
        <material name="rod_color" rgba="0.8 0.2 0.1 1"/>
        <material name="goal_green" rgba="0 1 0 1"/>
        <texture name="grid" type="2d" builtin="checker" rgb1=".1 .2 .3" rgb2=".2 .3 .4" width="300" height="300" mark="edge" markrgb=".2 .3 .4"/>
        <material name="grid" texture="grid" texrepeat="1 1" texuniform="true" reflectance=".2"/>

    </asset>

    <worldbody>
        <light name="light" pos="0 0 6"/>
        <geom name="floor" size="3 3 .2" type="plane" material="grid" conaffinity="7"/>

        <body name = "piston_rod" pos = "0 0.2 0.1">
            <joint name="rod" type="slide" axis="0 1 0" limited="true" range="-2 5"/>
            <geom name = "rod" type = "capsule"  size="0.06" mass = "1" fromto="0 0 0  0 0.4 0" material="rod_color" solimp = "0 0.4 0.001 0.5 0.2" solref = "0.06 0.8"/>
        </body>

        <body name="goal" pos = "0 1.0 0.2">
            <geom type = "box" size="0.1 0.1 0.1" mass="0.5" material="goal_green" solimp = "0 0.4 0.001 0.5 0.2" solref = "0.06 0.8" condim="1" margin = "0.001" contype = "3" conaffinity = "3"/>
            <joint type="free" />
        </body>

        <body pos="0 1.0 0" name="display_goal">
            <joint type="free" />
            <geom type = "box" pos = "0 0 0" size = ".1 .1 .1" rgba = "0 0 0 0" mass="1" margin = "0.001" contype = "4" conaffinity = "4" />
            <site type="box" pos="0 0 0.1" size="0.1 0.1 0.1" rgba="0 1 0 0.4"/>
        </body>

    </worldbody>

    <actuator>
        <!-- Actuator to control piston movement -->
        <motor name="piston_motor" joint="rod" ctrllimited="true" ctrlrange="-1 1" gear = "20"/>
    </actuator>
</mujoco>